Workbook

Sheet Investments
A1: WS Trade P | B1: DIV | C1: Balace YE | D1: Contrib | E1: Transfer | G1: Canada L | H1: Balace YE | I1: Contrib | Q1: WS Invest | R1: DIV | S1: Balace YE | T1: Contrib | U1: TD P | V1: DIV | W1: Balace YE | X1: Contrib | Y1: Variance
A2: 2016 | G2: 2016 | Q2: 2016 | U2: 2016 | V2: 264 | W2: 24461 | X2: =8303+13420.47 -> 21723.47 | Y2: =W2-X2 -> 2737.53
A3: 2017 | G3: 2017 | Q3: 2017 | U3: 2017 | V3: 947.65 | W3: 38303 | X3: 10000 | Y3: =W3-X3-W2 -> 3842 | Z3: =Y3/W3 -> 0.10030546
A4: 2018 | G4: 2018 | Q4: 2018 | T4: 100 | U4: 2018 | V4: 1452.31 | W4: 53958 | X4: 20000 | Y4: =W4-X4-W3 -> -4345 | Z4: =Y4/W4 -> -0.080525594
A5: 2019 | G5: 2019 | Q5: 2019 | R5: 369.48 | S5: 50390.93 | T5: 50000 | U5: 2019 | V5: 2086.32 | W5: 65888 | Y5: =W5-X5-W4 -> 11930 | Z5: =Y5/W5 -> 0.18106484
A6: 2020 | B6: 164 | C6: 11364 | D6: 10000 | G6: 2020 | H6: 6759 | I6: =H6 -> 6759 | Q6: 2020 | R6: =569.01+1460 -> 2029.01 | S6: 107597 | T6: 50000 | U6: 2020 | V6: 3832.46 | W6: 118697 | X6: 40000 | Y6: =W6-X6-W5 -> 12809 | Z6: =Y6/W6 -> 0.10791343
A7: 2021 | B7: 533 | C7: 14260 | G7: 2021 | H7: 22522 | I7: =6933+6933 -> 13866 | Q7: 2021 | R7: =637+1845 -> 2482 | S7: 121923 | U7: 2021 | V7: 4218 | W7: 154661 | Y7: =W7-X7-W6 -> 35964 | Z7: =Y7/W7 -> 0.23253438
A8: 2022 | B8: 2306 | C8: 137192 | D8: =20155 -> 20155 | E8: 108519 | G8: 2022 | H8: 35308 | I8: =7477+7477 -> 14954 | Q8: 2022 | R8: 635 | S8: 2 | U8: 2022 | V8: 4773.24 | W8: 134856 | Y8: =W8-X8-W7 -> -19805 | Z8: =Y8/W8 -> -0.14686035
A9: 2023 | B9: =Dividends!J4 -> 10962.86 | C9: 154754 | D9: 2350 | G9: 2023 | H9: =28435.66+28420.28 -> 56855.94 | I9: =7789.89*2 -> 15579.78 | U9: 2023 | V9: =Dividends!J8 -> 6675.31 | W9: 163382.29 | Y9: =W9-X9-W8 -> 28526.29 | Z9: =Y9/W9 -> 0.17459842
A10: 2024 | B10: =Dividends!L4 -> 21192 | C10: 427038 | E10: =334668-140655 -> 194013 | G10: 2024 | H10: =43799+43758 -> 87557 | I10: =1506+7032+8539 -> 17077 | U10: 2024 | V10: =Dividends!L8 -> 1790.73 | W10: 115
B11: =SUM(B6:B10) -> 35157.86 | D11: =SUM(D2:D10) -> 32505 | I11: =SUM(I6:I10) -> 68235.78 | R11: =SUM(R5:R8) -> 5515.49 | T11: =SUM(T4:T8) -> 100100 | V11: =SUM(V2:V10) -> 26040.02 | X11: =SUM(X2:X8) -> 91723.47 | Y11: =SUM(Y2:Y8) -> 43132.53 | Z11: =Y11/X11 -> 0.47024529
A13: WS Trade S | B13: DIV | C13: Balace YE | D13: Contrib | E13: Transfer | F13: BNS Stocks | G13: DIV | H13: Balace YE | I13: Contrib | J13: WS Spousal S | K13: Balace YE | L13: Contrib | M13: WS TFSA S | N13: Balace YE | O13: Contrib | Q13: QT S | R13: DIV | S13: Balace YE | T13: Contrib
F14: 2016 | G14: =7.01+15.18+21.38+29.18+14.03+30.36+42.75+58.35 -> 218.24 | H14: 10596 | I14: =26*(90.38+180.75) -> 7049.38 | Q14: 2016
F15: 2017 | G15: =34.96+42.5+48.41+57.43+69.92+84.99+96.81+114.86 -> 549.88 | H15: 19544 | I15: =26*(95.24+184.73) -> 7279.22 | Q15: 2017
F16: 2018 | G16: =63.45+73.4+80.25+91.61+126.89+146.8+160.49+183.2 -> 926.09 | H16: 23938 | I16: =26*(96.97+193.34) -> 7548.06 | Q16: 2018 | R16: 6.85 | S16: 962 | T16: 1000
F17: 2019 | G17: 1406 | H17: 35509 | I17: =26*(118.33+197.21) -> 8204.04 | Q17: 2019 | R17: 77 | S17: 6782 | T17: 5500
F18: 2020 | G18: 1984 | H18: 45399 | I18: =26*(121.87+203.12) -> 8449.74 | Q18: 2020 | R18: 291 | S18: 19182 | T18: 10000
F19: 2021 | G19: 2566 | H19: 71647 | I19: =26*(121.87+203.12) -> 8449.74 | Q19: 2021 | R19: 417 | S19: 22032 | T19: 0
F20: 2022 | G20: 3460 | H20: 63460 | I20: =26*(124.63+207.72) -> 8641.1 | Q20: 2022 | R20: 733 | S20: 23110 | T20: 3050
F21: 2023 | G21: =Dividends!J7 -> 4293.98 | H21: 74790 | I21: =26*(127.13+211.88) -> 8814.26 | Q21: 2023 | R21: =Dividends!J10 -> 1077.22 | S21: 30219 | T21: 3050
A22: 2024 | B22: =Dividends!L6 -> 1108.52 | C22: 39411 | D22: 1700 | E22: 34167 | F22: 2024 | G22: =Dividends!L7 -> 5259.75 | H22: 106012 | I22: =26*(128.16+213.6) -> 8885.76 | J22: 2024 | K22: 59543 | L22: 52000 | M22: 2024 | N22: 31964 | O22: =40000-3976-5137 -> 30887 | Q22: 2024 | R22: =Dividends!L10 -> 268.5 | S22: 228
G23: =SUM(G14:G20) -> 11110.21 | I23: =SUM(I14:I20) -> 55621.28 | R23: =SUM(R14:R20) -> 1524.85 | T23: =SUM(T14:T22) -> 22600
A25: Summary Dividends | L25: Summary Balance YE
B27: Dividends | C27: Balace YE | D27: Contrib | F27: Div Yeld | H27: Port Yeld | I27: Port Yeld w/o Div | L27: Account | M27: 2024 | O27: Div Yeld | P27: 2023 | R27: 2022
A28: 2016 | B28: =V2+R2+B2+G14+R14 -> 482.24 | C28: =W2+S2+C2+H14+H2+S14 -> 35057 | D28: =X2+T2+D2+I14+I2+T14 -> 28772.85 | F28: =B28/C28 -> 0.013755883 | L28: =A1 -> WS Trade P | M28: =C10 -> 427038 | N28: =M28/$M$37 -> 0.5682286 | O28: =B10/C10 -> 0.04962556 | P28: =C9 -> 154754 | Q28: =P28/$P$37 -> 0.32105025 | R28: =C8 -> 137192 | S28: =R28/$R$37 -> 0.34826846
A29: 2017 | B29: =V3+R3+B3+G15+R15 -> 1497.53 | C29: =W3+S3+C3+H15+H3+S15 -> 57847 | D29: =X3+T3+D3+I15+I3+T15 -> 17279.22 | F29: =B29/C29 -> 0.025887773 | H29: =(C29-D29-C28)/C28 -> 0.15719485 | I29: =H29-F29 -> 0.13130708 | L29: =F13 -> BNS Stocks | M29: =H22 -> 106012 | N29: =M29/$M$37 -> 0.14106251 | O29: =G22/H22 -> 0.049614666 | P29: =H21 -> 74790 | Q29: =P29/$P$37 -> 0.15515818 | R29: =H20 -> 63460 | S29: =R29/$R$37 -> 0.16109625
A30: 2018 | B30: =V4+R4+B4+G16+R16 -> 2385.25 | C30: =W4+S4+C4+H16+H4+S16 -> 78858 | D30: =X4+T4+D4+I16+I4+T16 -> 28648.06 | F30: =B30/C30 -> 0.030247407 | H30: =(C30-D30-C29)/C29 -> -0.13202171 | I30: =H30-F30 -> -0.16226912 | L30: =G1 -> Canada L | M30: =H10 -> 87557 | N30: =M30/$M$37 -> 0.11650577 | P30: =H9 -> 56855.94 | Q30: =P30/$P$37 -> 0.11795245 | R30: =H8 -> 35308 | S30: =R30/$R$37 -> 0.089631047
A31: 2019 | B31: =Dividends!C11 -> 3939.12 | C31: =W5+S5+C5+H17+H5+S17 -> 158569.93 | D31: =X5+T5+D5+I17+I5+T17 -> 63704.04 | F31: =B31/C31 -> 0.024841532 | H31: =(C31-D31-C30)/C30 -> 0.2029964 | I31: =H31-F31 -> 0.17815487 | L31: =J13 -> WS Spousal S | M31: =K22 -> 59543 | N31: =M31/$M$37 -> 0.079229567
A32: 2020 | B32: =Dividends!D11 -> 8300.28 | C32: =W6+S6+C6+H18+H6+S18 -> 308998 | D32: =X6+T6+D6+I18+I6+T18 -> 125208.74 | F32: =B32/C32 -> 0.026861921 | H32: =(C32-D32-C31)/C31 -> 0.15904232 | I32: =H32-F32 -> 0.1321804 | L32: =A13 -> WS Trade S | M32: =C22 -> 39411 | N32: =M32/$M$37 -> 0.052441369 | O32: =B22/C22 -> 0.028127173
A33: 2021 | B33: =Dividends!E11 -> 10218.23 | C33: =W7+S7+C7+H19+H7+S19 -> 407045 | D33: =X7+T7+D7+I19+I7+T19 -> 22315.74 | F33: =B33/C33 -> 0.025103441 | H33: =(C33-D33-C32)/C32 -> 0.24508657 | I33: =H33-F33 -> 0.21998313 | L33: =M13 -> WS TFSA S | M33: =N22 -> 31964 | N33: =M33/$M$37 -> 0.042532185
A34: 2022 | B34: =Dividends!G11 -> 11907.47 | C34: =W8+S8+C8+H20+H8+S20 -> 393928 | D34: =X8+T8+D8+I20+I8+T20 -> 46800.1 | F34: =B34/C34 -> 0.030227529 | H34: =(C34-D34-C33)/C33 -> -0.14720019 | I34: =H34-F34 -> -0.17742772 | L34: =U1 -> TD P | M34: =W10 -> 115 | N34: =M34/$M$37 -> 0.00015302219 | P34: =W9 -> 163382.29 | Q34: =P34/$P$37 -> 0.33895037 | R34: =W8 -> 134856 | S34: =R34/$R$37 -> 0.34233841
A35: 2023 | B35: =Dividends!J11 -> 23009.37 | C35: =W9+S9+C9+H21+H9+S21 -> 480001.23 | D35: =X9+T9+D9+I21+I9+T21 -> 29794.04 | F35: =B35/C35 -> 0.047936065 | H35: =(C35-D35-C34)/C34 -> 0.14286669 | I35: =H35-F35 -> 0.094930627 | L35: =Q13 -> QT S | M35: =S22 -> 228 | N35: =M35/$M$37 -> 0.00030338312 | P35: =S21 -> 30219 | Q35: =P35/$P$37 -> 0.062691869 | R35: =S20 -> 23110 | S35: =R35/$R$37 -> 0.058665841
A36: 2024 | B36: =Dividends!L11 -> 30126.75 | C36: =W10+C10+H22+H10+S22+S22+C22+K22+N22 -> 752096 | D36: =T22+I10+I22+L22+D10+D22 -> 79662.76 | F36: =B36/C36 -> 0.040057054 | H36: =(C36-D36-C35)/C35 -> 0.40089899 | I36: =H36-F36 -> 0.36084194
M37: =SUM(M28:M33) -> 751525 | N37: =(M37-P37)/P37 -> 0.55910212 | P37: =SUM(P27:P35) -> 482024.23 | Q37: =P37/R37-1 -> 0.22364157 | R37: =SUM(R28:R35) -> 393926
A38: All | B38: =SUM(B28:B36) -> 91866.24 | D38: =SUM(D28:D36) -> 442185.55 | H38: =SUM(H29:H37) -> 1.0288639
F40: 0.08 | G40: Target
A41: 2023 | B41: =Dividends!J11 -> 23009.37 | C41: =C34*1.05+D41 -> 442269.5 | D41: =I20+I8+T20+2000 -> 28645.1 | F41: =F40*C34 -> 31514.24 | G41: Amount
F42: =B41/C41 -> 0.052025677

Sheet Dividends
C1: 2019 | D1: 2020 | E1: 2021 | F1: Variance | G1: 2022 | H1: 2023 | J1: 2023 | L1: 2024 | N1: 2025
N3: Last year | O3: Stock Break
A4: WS Trade Paulo | C4: 0 | D4: =32.16+29.18+45.57+50.3+6.8 -> 164.01 | E4: =71.18+29.46+54.02+47.88+30.08+60.27+46.71+28.93+45.57+55.1+29.27+34.99 -> 533.46 | F4: =G4/E4-1 -> 3.3227796 | G4: =464.77+147.52+191.29+413.01+147.42+147.35+419.15+49.26+73.51+148.5+30.11+74.14 -> 2306.03 | H4: 8000 | I4: =J4/G4-1 -> 3.7539971 | J4: =187.46+150.56+838.26+705.74+914.09+1537.85+953.93+942.81+1484.11+910.42+880.99+1456.64 -> 10962.86 | K4: =L4/J4-1 -> 0.93307221 | L4: =1056+946+1644+1758+1435+2428+1763+1454+2194+2154+1527+2833 -> 21192 | M4: =N4/L4-1 -> 0.35247263 | N4: =(2154+1527+2833)*4*1.1 -> 28661.6 | O4: =SUM('Breakdow stocks - 17Mar25'!T2:T22) -> 24141.117
A5: WS Trade Simone | L5: =12.76+47.42+51.2+64.67+53.68+52.97+69.72+42.62+46.92+65.29 -> 507.25 | M5: =N5/L5-1 -> 5.5056678 | N5: 3300 | O5: =SUM('Breakdow stocks - 17Mar25'!T22:T29) -> 2936.4883
A6: WS TFSA Simone | L6: =157.01+172.69+142.19+164.42+141.18+122.75+115.7+92.58 -> 1108.52 | M6: =N6/L6-1 -> 0.44336593 | N6: 1600 | O6: =SUM('Breakdow stocks - 17Mar25'!T30:T31) -> 1423.157
A7: BNS | C7: 1406.32 | D7: 1983.81 | E7: =208.02+219.67+231.83+242.8+385.87+405.8+426.52+445.27 -> 2565.78 | F7: =G7/E7-1 -> 0.34868929 | G7: 3460.44 | H7: =G7*(1+F7) -> 4667.0584 | I7: =J7/G7-1 -> 0.24087688 | J7: =350.92+367.28+397.99+417.02+634.34+662.33+715.76+748.34 -> 4293.98 | K7: =L7/J7-1 -> 0.22491255 | L7: =440+460.95+483.45+504+788.6+823.53+861.96+897.26 -> 5259.75 | M7: =N7/L7-1 -> 0.24087688 | N7: =L7*(1+I7) -> 6526.7022 | O7: ='Breakdow stocks - 17Mar25'!T37 -> 5953.2826
A8: TD Waterhouse | C8: 2086.32 | D8: 3832.35 | E8: 4218.54 | F8: =G8/E8-1 -> 0.13149099 | G8: 4773.24 | H8: 6000 | I8: =J8/G8-1 -> 0.39848614 | J8: 6675.31 | L8: 1790.73
A9: WS Invest Paulo | C9: 369.48 | D9: 2029.11 | E9: =637.4+1845.88 -> 2483.28 | F9: =G9/E9-1 -> -0.74438646 | G9: =340.96+(226*1.3) -> 634.76 | H9: 0
A10: Questrade Simone | C10: 77 | D10: 291 | E10: 417.17 | F10: =G10/E10-1 -> 0.75707745 | G10: 733 | H10: 1000 | I10: =J10/G10-1 -> 0.46960437 | J10: 1077.22 | L10: 268.5
A11: Total year | C11: =SUM(C3:C10) -> 3939.12 | D11: =SUM(D3:D10) -> 8300.28 | E11: =SUM(E3:E10) -> 10218.23 | F11: =SUM(F3:F10) -> 3.8156509 | G11: =SUM(G3:G10) -> 11907.47 | H11: =SUM(H3:H8) -> 18667.058 | I11: =J11/G11-1 -> 0.93234751 | J11: =SUM(J4:J10) -> 23009.37 | K11: =L11/J11-1 -> 0.30932529 | L11: =SUM(L4:L10) -> 30126.75 | N11: =SUM(N4:N10) -> 40088.302 | O11: =SUM(O4:O10) -> 34454.045
D12: =D11/C11-1 -> 1.1071407 | E12: =E11/D11-1 -> 0.23107052 | F12: =F11/E11-1 -> -0.99962658 | G12: =G11/E11-1 -> 0.1653163 | J12: =J11/G11-1 -> 0.93234751 | L12: =L11/J11-1 -> 0.30932529 | N12: =N11/L11-1 -> 0.33065472
A13: Average month | C13: =C11/12 -> 328.26 | D13: =D11/12 -> 691.69 | E13: =E11/12 -> 851.51917 | G13: =G11/12 -> 992.28917 | H13: =H11/12 -> 1555.5882 | J13: =J11/12 -> 1917.4475 | L13: =L11/12 -> 2510.5625 | N13: =N11/12 -> 3340.6918 | O13: =O11/12 -> 2871.1704

Sheet Investment Overview
B2: Company | C2: Type | D2: Holder | E2: Current $
B3: Wealthsimple | C3: RSP | D3: Paulo Freitas | E3: 373335
B4: Wealthsimple | C4: Spousal RSP | D4: Simone Amaral | E4: 54947
B5: Wealthsimple | C5: RSP | D5: Simone Amaral | E5: 50306
B6: Wealthsimple | C6: TFSA | D6: Simone Amaral | E6: 40654
B7: Solium | C7: RSP | D7: Simone Amaral | E7: 81066
B8: Canada Life | C8: RSP | D8: Paulo Freitas | E8: 66000
B9: Questrade | C9: TFSA | D9: Simone Amaral | E9: 34248
E10: =SUM(E3:E9) -> 700556
B12: Morgan Stanley | C12: RSP | D12: Paulo Freitas | E12: 205088 | F12: To be received over next 3 years

Sheet Breakdow stocks - 17Mar25
B1: Account | C1: Stock | D1: Security type | E1: Strategy Type | F1: Call | G1: Sector | H1: Market | I1: Currency | J1: Fund magt | K1: Mang fee | L1: Book cost | M1: Market Value | N1: Profit/ loss | O1: Yeld | P1: 1 Year return | Q1: 5 Year return | R1: Risk | S1: Volatiity/Stanrd deviation | T1: Expected Annual Div | U1: External rating | V1: 1.44002
A2: 1 | B2: WS Trade P | C2: BTCC.B | D2: ETF | E2: Growth | F2: No | G2: Bitcoin | H2: USA | I2: CAD | K2: 0.0141 | L2: 2933 | M2: 5831 | N2: =M2-L2 -> 2898 | O2: 0 | P2: 0.2234 | Q2: 0.593 | R2: Extreme | S2: 0.6247 | T2: =O2*M2 -> 0
A3: 2 | B3: WS Trade P | C3: CM | D3: Company | E3: Mix | F3: No | G3: Banking | H3: Canada | I3: CAD | J3: N/A | K3: 0 | L3: 14915 | M3: 16342 | N3: =M3-L3 -> 1427 | O3: 0.0464 | P3: 0.2022 | Q3: 1.018 | T3: =O3*M3 -> 758.2688
A4: 3 | B4: WS Trade P | C4: Costco | D4: Company | E4: Growth | F4: No | G4: Consumer Defensive | H4: Global | I4: USD | K4: 0 | L4: =2372*$V$1 -> 3415.7274 | M4: =3197*$V$1 -> 4603.7439 | N4: =M4-L4 -> 1188.0165 | O4: 0.005 | P4: 0.2581 | Q4: 2.3058 | T4: =O4*M4 -> 23.01872
A5: 4 | B5: WS Trade P | C5: CYBR | D5: ETF | E5: Growth | F5: No | G5: Cybersecurity | H5: Global | I5: CAD | K5: 0.0063 | L5: 2271 | M5: 2953 | N5: =M5-L5 -> 682 | O5: 0.0023 | P5: 0.0763 | Q5: 1.3402 | R5: Very Aggressive | S5: 0.2051 | T5: =O5*M5 -> 6.7919
A6: 5 | B6: WS Trade P | C6: DFN | D6: Company | E6: Dividend | F6: No | G6: Asset Mgt | H6: Canada | I6: CAD | L6: 5746 | M6: 4227 | N6: =M6-L6 -> -1519 | O6: 0.2079 | P6: -0.0186 | Q6: 0.0721 | T6: =O6*M6 -> 878.7933
A7: 6 | B7: WS Trade P | C7: DOL | D7: Company | E7: Growth | F7: No | G7: Consumer Defensive | H7: Canada | I7: CAD | K7: 0 | L7: 11937 | M7: 14667 | N7: =M7-L7 -> 2730 | O7: 0.0024 | P7: 0.4241 | Q7: 1.1323 | T7: =O7*M7 -> 35.2008
A8: 7 | B8: WS Trade P | C8: ENB | D8: Company | E8: Mix | F8: No | G8: Energy | H8: Canada | I8: CAD | K8: 0 | L8: 17490 | M8: 23675 | N8: =M8-L8 -> 6185 | O8: 0.0598 | P8: 0.258 | Q8: 0.5313 | T8: =O8*M8 -> 1415.765
A9: 8 | B9: WS Trade P | C9: FIE | D9: ETF | E9: Mix | F9: No | G9: Finance | H9: Canada | I9: CAD | J9: Active | K9: 0.008 | L9: 9484 | M9: 10378 | N9: =M9-L9 -> 894 | O9: 0.0599 | P9: 0.1192 | Q9: 0.52 | R9: Aggressive | S9: 14.44 | T9: =O9*M9 -> 621.6422 | U9: 4 stars
A10: 9 | B10: WS Trade P | C10: FLI | D10: ETF | E10: Mix | F10: Yes | G10: Insurance | H10: North America | I10: CAD | L10: 14561 | M10: 16380 | N10: =M10-L10 -> 1819 | O10: 0.0626 | P10: 0.079 | Q10: 0.5176 | T10: =O10*M10 -> 1025.388
A11: 10 | B11: WS Trade P | C11: GWO | D11: Company | E11: Mix | F11: No | G11: Insurance | H11: Global | I11: CAD | K11: 0 | L11: 4277 | M11: 7547 | N11: =M11-L11 -> 3270 | O11: 0.0437 | P11: 0.2028 | Q11: 0.9434 | T11: =O11*M11 -> 329.8039
A12: 11 | B12: WS Trade P | C12: HDIV | D12: ETF | E12: Dividend | F12: Yes | G12: Mix | H12: North America | I12: CAD | J12: Passive | L12: 15551 | M12: 16235 | N12: =M12-L12 -> 684 | O12: 0.1197 | P12: 0.0323 | Q12: 0.026 | R12: Very Aggressive | S12: 0.1979 | T12: =O12*M12 -> 1943.3295 | U12: 4 AsarA
A13: 12 | B13: WS Trade P | C13: HMAX | D13: ETF | E13: Dividend | F13: Yes | G13: Finance | H13: Canada | I13: CAD | J13: Active | L13: 11943 | M13: 11024 | N13: =M13-L13 -> -919 | O13: 0.1488 | P13: -0.0303 | Q13: -0.1536 | T13: =O13*M13 -> 1640.3712
A14: 13 | B14: WS Trade P | C14: HYLD | D14: ETF | E14: Dividend | F14: Yes | G14: Mix | H14: North America | I14: CAD | J14: Active | L14: 22543 | M14: 23782 | N14: =M14-L14 -> 1239 | O14: 0.1348 | P14: -0.0407 | Q14: -0.2114 | T14: =O14*M14 -> 3205.8136
A15: 14 | B15: WS Trade P | C15: RY | D15: Company | E15: Mix | F15: No | G15: Banking | H15: Canada | I15: CAD | J15: N/A | K15: 0 | L15: 13556 | M15: 14492 | N15: =M15-L15 -> 936 | O15: 0.0358 | P15: 0.1789 | Q15: 0.9998 | T15: =O15*M15 -> 518.8136
A16: 15 | B16: WS Trade P | C16: TXF | D16: ETF | E16: Mix | F16: Yes | G16: IT | H16: North America | I16: CAD | J16: Active | L16: 26095 | M16: 26956 | N16: =M16-L16 -> 861 | O16: 0.1078 | P16: -0.1137 | Q16: 0.3757 | S16: High | T16: =O16*M16 -> 2905.8568
A17: 16 | B17: WS Trade P | C17: VGT | D17: ETF | E17: Growth | F17: No | G17: IT | H17: USA | I17: USD | J17: Passive | L17: =25176*$V$1 -> 36253.944 | M17: =60586*$V$1 -> 87245.052 | N17: =M17-L17 -> 50991.108 | O17: 0.0068 | P17: 0.0509 | Q17: 1.7398 | S17: Normal | T17: =O17*M17 -> 593.26635
A18: 17 | B18: WS Trade P | C18: XUT | D18: ETF | E18: Mix | F18: No | G18: Utility | H18: North America | I18: CAD | J18: Passive | L18: 8532 | M18: 8556 | N18: =M18-L18 -> 24 | O18: 0.04 | P18: 0.1244 | Q18: 0.2056 | S18: Stable | T18: =O18*M18 -> 342.24
A19: 18 | B19: WS Trade P | C19: ZSP | D19: ETF | E19: Growth | F19: No | G19: S&P | H19: USA | I19: CAD | J19: Passive | L19: 23215 | M19: 26016 | N19: =M19-L19 -> 2801 | O19: 0.0098 | P19: 0.1524 | Q19: 1.2584 | S19: Normal | T19: =O19*M19 -> 254.9568
A20: 19 | B20: WS Trade P | C20: ZWG | D20: ETF | E20: Mix | F20: Yes | G20: Mix | H20: Global | I20: CAD | J20: Active | L20: 50732 | M20: 52682 | N20: =M20-L20 -> 1950 | O20: 0.0648 | P20: 0.058 | Q20: 0.2204 | S20: Normal | T20: =O20*M20 -> 3413.7936
A21: 20 | B21: WS Trade P | C21: ZWK | D21: ETF | E21: Mix | F21: Yes | G21: Banking | H21: USA | I21: CAD | L21: 31996 | M21: 40356 | N21: =M21-L21 -> 8360 | O21: 0.0777 | P21: 0.1255 | Q21: 0.1409 | S21: Normal | T21: =O21*M21 -> 3135.6612
A22: 1 | B22: WS Trade S | C22: CLM | D22: Fund | E22: Growth | F22: No | G22: Asset Mgt | H22: Global | I22: USD | J22: Active | L22: =4524*$V$1 -> 6514.6505 | M22: =4400*$V$1 -> 6336.088 | N22: =M22-L22 -> -178.56248 | O22: 0.1724 | P22: 4.71 | Q22: 0.0858 | R22: Aggressive | S22: 16.7 | T22: =O22*M22 -> 1092.3416 | U22: 4 stars
A23: 2 | B23: WS Trade S | C23: FIE | D23: ETF | E23: Mix | F23: No | G23: Finance | H23: Canada | I23: CAD | J23: Active | L23: 10866 | M23: 10852 | N23: =M23-L23 -> -14 | O23: 0.0599 | P23: 0.1192 | Q23: 0.52 | S23: Normal | T23: =O23*M23 -> 650.0348
A24: 3 | B24: WS Trade S | C24: IGM | D24: ETF | E24: Growth | F24: No | G24: IT | H24: North America | I24: USD | J24: Passive | L24: =1647*$V$1 -> 2371.7129 | M24: =3260*$V$1 -> 4694.4652 | N24: =M24-L24 -> 2322.7523 | O24: 0.0024 | P24: 0.0804 | Q24: 1.7771 | S24: Normal | T24: =O24*M24 -> 11.266716
A25: 4 | B25: WS Trade S | C25: MFC | D25: Company | E25: MIx | F25: No | G25: Insurance | H25: Global | I25: CAD | J25: N/A | L25: 2146 | M25: 4290 | N25: =M25-L25 -> 2144 | O25: 0.0398 | P25: 0.3042 | Q25: 1.3471 | S25: High | T25: =O25*M25 -> 170.742
A26: 5 | B26: WS Trade S | C26: TJX | D26: Company | E26: Growth | F26: No | G26: Consumer Cyclical | H26: North America | I26: USD | J26: N/A | K26: 0 | L26: =2988*V1 -> 4302.7798 | M26: =3075*V1 -> 4428.0615 | N26: =M26-L26 -> 125.28174 | O26: 0.013 | P26: 0.1975 | Q26: 1.9144 | T26: =O26*M26 -> 57.564799
A27: 6 | B27: WS Trade S | C27: VFV | D27: ETF | E27: Growth | F27: No | G27: S&P | H27: USA | I27: CAD | J27: Passive | L27: 6681 | M27: 7583 | N27: =M27-L27 -> 902 | O27: 0.0103 | P27: 0.1528 | Q27: 1.2643 | S27: Normal | T27: =O27*M27 -> 78.1049
A28: 7 | B28: WS Trade S | C28: XHU | D28: ETF | E28: Growth | F28: No | G28: Mix | H28: USA | I28: CAD | J28: Passive | L28: 7004 | M28: 7335 | N28: =M28-L28 -> 331 | O28: 0.0273 | P28: 0.1616 | Q28: 0.6478 | S28: Normal | T28: =O28*M28 -> 200.2455
A29: 8 | B29: WS Trade S | C29: ZWG | D29: ETF | E29: Mix | F29: Yes | G29: Mix | H29: Global | I29: CAD | J29: Active | L29: 10604 | M29: 10435 | N29: =M29-L29 -> -169 | O29: 0.0648 | P29: 0.058 | Q29: 0.2204 | S29: Normal | T29: =O29*M29 -> 676.188
B30: WS TFSA | C30: TILV | D30: ETF | E30: Growth | F30: No | G30: Mix | H30: Global | I30: CAD | J30: Active | K30: 0.004 | L30: 29997 | M30: 30030 | N30: =M30-L30 -> 33 | O30: 0.0305 | P30: 0.1772 | Q30: 0.5029 | S30: Low | T30: =O30*M30 -> 915.915
B31: WS TFSA | C31: ZLN | D31: ETF | E31: Growth | F31: No | G31: Mix | H31: Canada | I31: CAD | J31: Active | K31: 0.004 | L31: 22039 | M31: 22054 | N31: =M31-L31 -> 15 | O31: 0.023 | P31: 0.1246 | Q31: 0.7604 | S31: Low | T31: =O31*M31 -> 507.242
B32: WS Spousal | C32: VTI | D32: ETF | E32: Growth | F32: No | G32: Mix | H32: USA | I32: CAD | J32: Active | K32: =0.4% -> 0.004 | M32: =60977*W32 -> 17805.284 | O32: 0.0133 | P32: 0.0952 | Q32: 1.2852 | T32: =O32*M32 -> 236.81028 | W32: 0.292
B33: WS Spousal | C33: IEFA,EEMV,GLOV | D33: ETF | E33: Growth | F33: No | G33: Mix | H33: Global | I33: CAD | J33: Active | K33: 0.004 | M33: =60977*W33 -> 30183.615 | T33: =O33*M33 -> 0 | W33: =22.6%+15.4%+11.5% -> 0.495
B34: WS Spousal | C34: QCN | D34: ETF | E34: Growth | F34: No | G34: Mix | H34: Canada | I34: CAD | J34: Active | K34: =0.4%+0.04% -> 0.0044 | M34: =60977*W34 -> 6829.424 | O34: 0.0275 | P34: 14.41 | Q34: 0.9535 | T34: =O34*M34 -> 187.80916 | W34: 0.112
B35: WS Spousal | C35: ZFL | D35: ETF | E35: Growth | F35: No | G35: Bond | H35: North America | I35: CAD | J35: Active | K35: =0.4%+0.22% -> 0.0062 | M35: =60977*W35 -> 4451.321 | O35: 0.0307 | P35: 0.0389 | Q35: -0.3344 | T35: =O35*M35 -> 136.65555 | W35: 0.073
B36: WS Spousal | C36: GLDM | D36: ETF | E36: Growth | F36: No | G36: Gold | H36: Global | I36: CAD | J36: Active | K36: =0.4%+0.1% -> 0.005 | M36: =60977*W36 -> 1524.425 | O36: 0 | P36: 0.3875 | Q36: 1.0013 | T36: =O36*M36 -> 0 | W36: 0.025
B37: BNS ESOP | C37: BNS | D37: Company | E37: Mix | F37: No | G37: Banking | H37: Canada | I37: CAD | J37: N/A | K37: 0 | L37: =35654+63374 -> 99028 | M37: =62024+34935 -> 96959 | N37: =M37-L37 -> -2069 | O37: 0.0614 | P37: 0.0153 | Q37: 0.2916 | S37: Normal | T37: =O37*M37 -> 5953.2826
B38: Canada Life RRS P | C38: BR LP 2040 | D38: Fund | E38: Growth | F38: No | G38: Mix | H38: Global | I38: CAD | K38: 0.00084 | M38: 22713 | P38: 0.1976 | Q38: =8.88*5% -> 0.444 | S38: Normal | T38: =O38*M38 -> 0
B39: Canada Life RRS P | C39: BR LP 2060 | D39: Fund | E39: Growth | F39: No | G39: Mix | H39: Global | I39: CAD | K39: 0.00089 | M39: 7480 | P39: 0.25 | Q39: =10.95*5% -> 0.5475 | S39: Normal | T39: =O39*M39 -> 0
B40: Canada Life RRS P | C40: US Equity index | D40: Fund | E40: Growth | F40: No | G40: S&P | H40: USA | I40: CAD | J40: Passive | K40: 0.00053 | M40: 7976 | P40: 0.3593 | Q40: =5*0.1657 -> 0.8285 | S40: Normal | T40: =O40*M40 -> 0
...

Sheet Breakdown dashboard
E1: Row Labels | F1: Sum of Market Value | J1: Row Labels | K1: Sum of Market Value
A2: Row Labels | B2: Sum of Market Value | E2: Mix | F2: 290760.32 | J2: Dividend | K2: 55268
A3: Canada | B3: 231499.42 | E3: Banking | F3: 168149 | J3: Growth | K3: 375917.48
A4: Global | B4: 223973.87 | E4: IT | F4: 118895.52 | J4: Mix | K4: 339900
A5: North America | B5: 105482.85 | E5: S&P | F5: 51557 | J5: Grand Total | K5: 771085.48
A6: USA | B6: 210129.34 | E6: Finance | F6: 32254
A7: Grand Total | B7: 771085.48 | E7: Insurance | F7: 28217
E8: Utility | F8: 8556
E9: Bitcoin | F9: 5831
E10: Bond | F10: 4451.321
E11: Gold | F11: 1524.425
E12: Grand Total | F12: 710195.59
E17: Row Labels | F17: Sum of Market Value | J17: Row Labels | K17: Sum of Market Value
A18: Row Labels | B18: Sum of Market Value | E18: No | F18: 573235.48 | J18: CAD | K18: 663778.07
A19: Company | B19: 191230.81 | C19: =GETPIVOTDATA("Market Value",$A$18,"Security type","Company")/GETPIVOTDATA("Market Value",$A$18) -> 0.24800208 | E19: Yes | F19: 197850 | J19: USD | K19: 107307.41
A20: ETF | B20: 482171.59 | C20: =GETPIVOTDATA("Market Value",$A$18,"Security type","ETF")/GETPIVOTDATA("Market Value",$A$18) -> 0.62531535 | E20: Grand Total | F20: 771085.48 | J20: Grand Total | K20: 771085.48
A21: Fund | B21: 97683.088 | C21: =GETPIVOTDATA("Market Value",$A$18,"Security type","Fund")/GETPIVOTDATA("Market Value",$A$18) -> 0.12668257
A22: Grand Total | B22: 771085.48
